<?xml version="1.0" ?>
<!-- =================================================================================== -->
<!-- |    This document was autogenerated by xacro from quadrotor_base.xacro           | -->
<!-- |    EDITING THIS FILE BY HAND IS NOT RECOMMENDED                                 | -->
<!-- =================================================================================== -->
<robot name="Lrobot" xmlns:xacro="http://www.ros.org/wiki/xacro">

  <link name="point_mass">
    <visual>
      <origin rpy="0 0 0" xyz="0 0 0"/>
      <geometry>
      <sphere radius="0.1"/>
      </geometry>
    </visual>

    <collision>
      <origin rpy="0 0 0" xyz="0 0 0"/>
      <geometry>
      <sphere radius="0.1"/>
      </geometry>
    </collision>


  </link>

  <link name="cable_1">
    <visual>
      <origin rpy="0 0 0" xyz="0 0 .25"/>
      <geometry>
      <cylinder length="0.5" radius="0.01"/>
      </geometry>
    </visual>

    <collision>
      <origin rpy="0 0 0" xyz="0 0 .25"/>
      <geometry>
      <cylinder length="0.5" radius="0.01"/>
      </geometry>
    </collision>

  </link>

  <link name="robot_1">
    <visual>
      <origin rpy="0 0 0" xyz="0 0 0"/>
      <geometry>
      <sphere radius="0.1"/>
      </geometry>
    </visual>

    <collision>
      <origin rpy="0 0 0" xyz="0 0 0"/>
      <geometry>
      <sphere radius="0.1"/>
      </geometry>
    </collision>


  </link>

  <link name="cable_2">
    <visual>
      <origin rpy="0 0 0" xyz="0 0 .25"/>
      <geometry>
      <cylinder length="0.5" radius="0.01"/>
      </geometry>
    </visual>
  </link>


  <link name="robot_2">
    <origin rpy="0 0 0" xyz="0 0 .25"/>
    <visual>
      <origin rpy="0 0 0" xyz="0 0 0"/>
      <geometry>
      <sphere radius="0.1"/>
      </geometry>
    </visual>

    <collision>
      <origin rpy="0 0 0" xyz="0 0 0"/>
      <geometry>
      <sphere radius="0.1"/>
      </geometry>
    </collision>


  </link>



  <link name="world">
  </link>


  <link name="x_link">
  </link>

  <link name="y_link">
  </link>

  <link name="z_link">
  </link>

  <joint name="x_j" type="prismatic">
  <parent link="world"/>
  <child link="x_link"/>
  <axis xyz="1 0 0"/>
  <limit effort="1000.0" lower="-2.0" upper="2.0" velocity="1.0"/>
  </joint>

  <joint name="y_j" type="prismatic">
  <parent link="x_link"/>
  <child link="y_link"/>
  <axis xyz="0 1 0"/>
  <limit effort="1000.0" lower="-2.0" upper="2.0" velocity="1.0"/>
  </joint>

  <joint name="z_j" type="prismatic">
  <parent link="y_link"/>
  <child link="z_link"/>
  <axis xyz="0 0 1"/>
  <limit effort="1000.0" lower="-2.0" upper="2.0" velocity="1.0"/>
  </joint>


  <joint name="base_j" type="fixed">
    <parent link="z_link"/>
    <child link="point_mass"/>
  </joint>

  <link name="_cable_1">
  </link>

  <link name="_cable_2">
  </link>

  <joint name="_cable_1j" type="revolute">
    <parent link="point_mass"/>
    <child link="_cable_1"/>
    <axis xyz="0 1 0"/>
    <limit effort="1000.0" lower="-3.14159" upper="3.14159" velocity="1.0"/>
  </joint>

  <joint name="_cable_2j" type="revolute">
    <parent link="point_mass"/>
    <child link="_cable_2"/>
    <axis xyz="0 1 0"/>
    <limit effort="1000.0" lower="-3.14159" upper="3.14159" velocity="1.0"/>
  </joint>

  <joint name="cable_1j" type="revolute">
    <parent link="_cable_1"/>
    <child link="cable_1"/>
    <axis xyz="1 0 0"/>
    <limit effort="1000.0" lower="-3.14159" upper="3.14159" velocity="1.0"/>
  </joint>

  <joint name="cable_2j" type="revolute">
    <parent link="_cable_2"/>
    <child link="cable_2"/>
    <axis xyz="1 0 0"/>
    <limit effort="1000.0" lower="-3.14159" upper="3.14159" velocity="1.0"/>
  </joint>

  <joint name="robot_1j" type="fixed">
    <parent link="cable_1"/>
    <child link="robot_1"/>
    <origin rpy="0 0 0" xyz="0 0 0.5"/>
  </joint>

  <joint name="robot_2j" type="fixed">
    <parent link="cable_2"/>
    <child link="robot_2"/>
    <origin rpy="0 0 0" xyz="0 0 0.5"/>
  </joint>

  <link name="obs1">
    <visual>
      <origin rpy="0 0 0" xyz="0 -0.8 0"/>
      <geometry>
      <box size="0.1 1 3"/>
      </geometry>
    </visual>

    <collision>
      <origin rpy="0 0 0" xyz="0 -0.8 0"/>
      <geometry>
      <box size="0.1 1 3"/>
      </geometry>
    </collision>

  </link>

  <link name="obs2">
    <visual>
      <origin rpy="0 0 0" xyz="0 0.8 0"/>
      <geometry>
      <box size="0.1 1 3"/>
      </geometry>
    </visual>

    <collision>
      <origin rpy="0 0 0" xyz="0 0.8 0"/>
      <geometry>
      <box size="0.1 1 3"/>
      </geometry>
    </collision>


  </link>

  <joint name="obs1_j" type="fixed">
  <parent link="world"/>
  <child link="obs1"/>
  </joint>

  <joint name="obs2_j" type="fixed">
    <parent link="world"/>
    <child link="obs2"/>
  </joint>




</robot>
