<?xml version="1.0" ?>
<!-- =================================================================================== -->
<!-- |    This document was autogenerated by xacro from quadrotor_base.xacro           | -->
<!-- |    EDITING THIS FILE BY HAND IS NOT RECOMMENDED                                 | -->
<!-- =================================================================================== -->
<robot name="Lrobot" xmlns:xacro="http://www.ros.org/wiki/xacro">
  <link name="base_link">
    <visual>
      <origin rpy="0 0 0" xyz="0 0 0"/>
      <geometry>
      <box size="0.5 0.1 0.1"/>
      </geometry>
    </visual>

    <collision>
      <origin rpy="0 0 0" xyz="0 0 0"/>
      <geometry>
      <box size="0.5 0.1 0.1"/>
      </geometry>
    </collision>


    <visual>
      <origin rpy="0 0 0" xyz=".3 .2 0"/>
      <geometry>
      <box size="0.1 0.5 0.1"/>
      </geometry>
    </visual>

    <collision>
      <origin rpy="0 0 0" xyz=".3 .2 0"/>
      <geometry>
      <box size="0.1 0.5 0.1"/>
      </geometry>
    </collision>


  </link>

  <link name="world">
  </link>

  <link name="obs1">
    <visual>
      <origin rpy="0 0 0" xyz="1 -1.2 0"/>
      <geometry>
      <box size="0.1 2. 2."/>
      </geometry>
    </visual>

    <collision>
      <origin rpy="0 0 0" xyz="1 -1.2 0"/>
      <geometry>
      <box size="0.1 2. 2."/>
      </geometry>
    </collision>



    <visual>
      <origin rpy="0 0 0" xyz="1 1.2 0"/>
      <geometry>
      <box size="0.1 2. 2."/>
      </geometry>
    </visual>

    <collision>
      <origin rpy="0 0 0" xyz="1 1.2 0"/>
      <geometry>
      <box size="0.1 2. 2."/>
      </geometry>
    </collision>



    <visual>
      <origin rpy="0 0 0" xyz="1 0 -1"/>
      <geometry>
      <box size="0.1 .4 .4"/>
      </geometry>
    </visual>

    <collision>
      <origin rpy="0 0 0" xyz="1 0 -1"/>
      <geometry>
      <box size="0.1 .4 .4"/>
      </geometry>
    </collision>

    <visual>
      <origin rpy="0 0 0" xyz="1 0 1"/>
      <geometry>
      <box size="0.1 .4 .4"/>
      </geometry>
    </visual>

    <collision>
      <origin rpy="0 0 0" xyz="1 0 1"/>
      <geometry>
      <box size="0.1 .4 .4"/>
      </geometry>
    </collision>



    <!--
    <visual>
      <origin rpy="0 0 0" xyz=".3 .2 0"/>
      <geometry>
      <box size="0.1 0.5 0.1"/>
      </geometry>
    </visual>
    -->

  </link>




  <joint name="myjoint" type="floating">
  <parent link="world"/>
  <child link="base_link"/>
  </joint>

  <joint name="obs1_j" type="fixed">
  <parent link="world"/>
  <child link="obs1"/>
  </joint>


</robot>
