<?xml version="1.0" ?>
<!-- =================================================================================== -->
<!-- |    This document was autogenerated by xacro from quadrotor_base.xacro           | -->
<!-- |    EDITING THIS FILE BY HAND IS NOT RECOMMENDED                                 | -->
<!-- =================================================================================== -->
<robot name="unicycle" xmlns:xacro="http://www.ros.org/wiki/xacro">

  <link name="link_x">
  </link>

  <link name="link_y">
  </link>

  <link name="link_theta">
  </link>


  <link name="base_link">
    <visual>
      <origin rpy="0 0 0" xyz="0 0 0"/>
      <geometry>
      <box size="0.5 0.25 0.5"/>
      </geometry>
    </visual>

    <collision>
      <origin rpy="0 0 0" xyz="0 0 0"/>
      <geometry>
      <box size="0.5 0.25 0.5"/>
      </geometry>
    </collision>
  </link>

  <link name="world">
  </link>

  <link name="obs1">
    <visual>
      <origin rpy="0 0 0" xyz=".3 .3 0"/>
      <geometry>
      <box size="0.5 .25 1"/>
      </geometry>
    </visual>

    <collision>
      <origin rpy="0 0 0" xyz=".3 .3 0"/>
      <geometry>
      <box size="0.5 .25 1"/>
      </geometry>
    </collision>

    <visual>
      <origin rpy="0 0 0" xyz="1.1 0.3 0"/>
      <geometry>
      <box size="0.5 .25 1"/>
      </geometry>
    </visual>


    <collision>
      <origin rpy="0 0 0" xyz="1.1 0.3 0"/>
      <geometry>
      <box size="0.5 .25 1"/>
      </geometry>
    </collision>

    <visual>
      <origin rpy="0 0 0" xyz="2.7 0.3 0"/>
      <geometry>
      <box size="0.5 .25 1"/>
      </geometry>
    </visual>


    <collision>
      <origin rpy="0 0 0" xyz="2.7 0.3 0"/>
      <geometry>
      <box size="0.5 .25 1"/>
      </geometry>
    </collision>
  </link>
  <!---->
  <!-- min: [0.0, 0.0] -->
  <!-- max: [3.0, 1.2] -->

  <!-- <joint name="myjoint" type="planar"> -->
  <!-- <parent link="world"/> -->
  <!-- <child link="base_link"/> -->
  <!-- </joint> -->
  <joint name="join_x" type="prismatic">
  <parent link="world"/>
  <child link="link_x"/>
  <axis xyz="1 0 0"/>
  <limit effort="1000.0" lower="0.0" upper="3.0" velocity="1.0"/>
  </joint>

  <joint name="join_y" type="prismatic">
    <parent link="link_x"/>
    <child link="link_y"/>
    <axis xyz="0 1 0"/>
  <limit effort="1000.0" lower="0.0" upper="1.2" velocity="1.0"/>
  </joint>

  <joint name="join_theta" type="revolute">
    <parent link="link_y"/>
    <child link="link_theta"/>
    <axis xyz="0 0 1"/>
    <limit effort="1000.0" lower="-3.14159265359" upper= "3.14159265359" velocity="1.0"/>
  </joint>

  <joint name="join_base" type="fixed">
    <parent link="link_theta"/>
    <child link="base_link"/>
  </joint>

  <joint name="obs1_j" type="fixed">
  <parent link="world"/>
  <child link="obs1"/>
  </joint>


</robot>
