<?xml version="1.0" encoding="utf-8"?>
<!-- =================================================================================== -->
<!-- |    This document was autogenerated by xacro from ur5_robot.urdf.xacro           | -->
<!-- |    EDITING THIS FILE BY HAND IS NOT RECOMMENDED                                 | -->
<!-- =================================================================================== -->
<robot name="ur5" xmlns:xacro="http://wiki.ros.org/xacro">
  <gazebo>
    <plugin filename="libgazebo_ros_control.so" name="ros_control">
      <!--robotNamespace>/</robotNamespace-->
      <!--robotSimType>gazebo_ros_control/DefaultRobotHWSim</robotSimType-->
    </plugin>
    <!--
    <plugin name="gazebo_ros_power_monitor_controller" filename="libgazebo_ros_power_monitor.so">
      <alwaysOn>true</alwaysOn>
      <updateRate>1.0</updateRate>
      <timeout>5</timeout>
      <powerStateTopic>power_state</powerStateTopic>
      <powerStateRate>10.0</powerStateRate>
      <fullChargeCapacity>87.78</fullChargeCapacity>
      <dischargeRate>-474</dischargeRate>
      <chargeRate>525</chargeRate>
      <dischargeVoltage>15.52</dischargeVoltage>
      <chargeVoltage>16.41</chargeVoltage>
    </plugin>
-->
  </gazebo>
  <!-- measured from model -->
  <!--property name="shoulder_height" value="0.089159" /-->
  <!--property name="shoulder_offset" value="0.13585" /-->
  <!-- shoulder_offset - elbow_offset + wrist_1_length = 0.10915 -->
  <!--property name="upper_arm_length" value="0.42500" /-->
  <!--property name="elbow_offset" value="0.1197" /-->
  <!-- CAD measured -->
  <!--property name="forearm_length" value="0.39225" /-->
  <!--property name="wrist_1_length" value="0.093" /-->
  <!-- CAD measured -->
  <!--property name="wrist_2_length" value="0.09465" /-->
  <!-- In CAD this distance is 0.930, but in the spec it is 0.09465 -->
  <!--property name="wrist_3_length" value="0.0823" /-->
  <!-- manually measured -->









  <link name="base_link">
    <visual>
      <geometry>
        <mesh filename="ur5/visual/base.dae"/>
      </geometry>
      <material name="LightGrey">
        <color rgba="0.7 0.7 0.7 1.0"/>
      </material>
    </visual>
    <collision>
      <origin rpy="0 0 0" xyz="0.0 0.0 0.025"/>
      <!-- <geometry> -->
      <!--   <mesh filename="/home/quim/stg/quim-example-robot-data/example-robot-data/robots/ur_description/meshes/ur5/collision/base.stl"/> -->
      <!-- </geometry> -->
      <geometry>
	<!-- <capsule length="0.1" radius="0.02"/> -->
	<sphere  radius="0.1"/>
      </geometry>
      <material>
        <color rgba="0.8 0.7 0.7 0.5"/>
      </material>
  </collision>
    <inertial>
      <mass value="4.0"/>
      <origin rpy="0 0 0" xyz="0.0 0.0 0.0"/>
      <inertia ixx="0.00443333156" ixy="0.0" ixz="0.0" iyy="0.00443333156" iyz="0.0" izz="0.0072"/>
    </inertial>
  </link>
  <joint name="shoulder_pan_joint" type="revolute">
    <parent link="base_link"/>
    <child link="shoulder_link"/>
    <origin rpy="0.0 0.0 0.0" xyz="0.0 0.0 0.089159"/>
    <axis xyz="0 0 1"/>
    <limit effort="150.0" lower="-6.28318530718" upper="6.28318530718" velocity="3.15"/>
    <dynamics damping="0.0" friction="0.0"/>
  </joint>
  <link name="shoulder_link">
    <visual>
      <geometry>
        <mesh filename="ur5/visual/shoulder.dae"/>
      </geometry>
      <material name="LightGrey">
        <color rgba="0.7 0.7 0.7 1.0"/>
      </material>
    </visual>
    <collision>
      <!-- <geometry> -->
      <!--   <mesh filename="/home/quim/stg/quim-example-robot-data/example-robot-data/robots/ur_description/meshes/ur5/collision/shoulder.stl"/> -->
      <!-- </geometry> -->
      <geometry>
	<sphere  radius="0.1"/>
      </geometry>
    </collision>
    <inertial>
      <mass value="3.7"/>
      <origin rpy="0 0 0" xyz="0.0 0.0 0.0"/>
      <inertia ixx="0.010267495893" ixy="0.0" ixz="0.0" iyy="0.010267495893" iyz="0.0" izz="0.00666"/>
    </inertial>
  </link>
  <joint name="shoulder_lift_joint" type="revolute">
    <parent link="shoulder_link"/>
    <child link="upper_arm_link"/>
    <origin rpy="0.0 1.57079632679 0.0" xyz="0.0 0.13585 0.0"/>
    <axis xyz="0 1 0"/>
    <limit effort="150.0" lower="-6.28318530718" upper="6.28318530718" velocity="3.15"/>
    <dynamics damping="0.0" friction="0.0"/>
  </joint>
  <link name="upper_arm_link">
    <visual>
      <geometry>
        <mesh filename="ur5/visual/upperarm.dae"/>
      </geometry>
      <material name="LightGrey">
        <color rgba="0.7 0.7 0.7 1.0"/>
      </material>
    </visual>
    <collision>
      <!-- <geometry> -->
      <!--   <mesh filename="/home/quim/stg/quim-example-robot-data/example-robot-data/robots/ur_description/meshes/ur5/collision/upperarm.stl"/> -->
      <!-- </geometry> -->
      <origin rpy="0 0 0" xyz="0.0 0.0 0.2"/>
    <geometry>
	<!-- <sphere  radius="0.1"/> -->
	<cylinder  radius="0.08" length=".55"/>
      </geometry>
    </collision>
    <inertial>
      <mass value="8.393"/>
      <origin rpy="0 0 0" xyz="0.0 0.0 0.28"/>
      <inertia ixx="0.22689067591" ixy="0.0" ixz="0.0" iyy="0.22689067591" iyz="0.0" izz="0.0151074"/>
    </inertial>
  </link>
  <joint name="elbow_joint" type="revolute">
    <parent link="upper_arm_link"/>
    <child link="forearm_link"/>
    <origin rpy="0.0 0.0 0.0" xyz="0.0 -0.1197 0.425"/>
    <axis xyz="0 1 0"/>
    <limit effort="150.0" lower="-3.14159265359" upper="3.14159265359" velocity="3.15"/>
    <dynamics damping="0.0" friction="0.0"/>
  </joint>
  <link name="forearm_link">
    <visual>
      <geometry>
        <mesh filename="ur5/visual/forearm.dae"/>
      </geometry>
      <material name="LightGrey">
        <color rgba="0.7 0.7 0.7 1.0"/>
      </material>
    </visual>
    <collision>
      <!-- <geometry> -->
      <!--   <mesh filename="/home/quim/stg/quim-example-robot-data/example-robot-data/robots/ur_description/meshes/ur5/collision/forearm.stl"/> -->
      <!-- </geometry> -->
        <origin rpy="0 0 0" xyz="0.0 0.0 0.15"/>
      <geometry>
	<!-- <sphere  radius="0.05"/> -->
        <cylinder  radius="0.05" length=".4"/>
      </geometry>
    </collision>
    <inertial>
      <mass value="2.275"/>
      <origin rpy="0 0 0" xyz="0.0 0.0 0.25"/>
      <inertia ixx="0.049443313556" ixy="0.0" ixz="0.0" iyy="0.049443313556" iyz="0.0" izz="0.004095"/>
    </inertial>
  </link>
  <joint name="wrist_1_joint" type="revolute">
    <parent link="forearm_link"/>
    <child link="wrist_1_link"/>
    <origin rpy="0.0 1.57079632679 0.0" xyz="0.0 0.0 0.39225"/>
    <axis xyz="0 1 0"/>
    <limit effort="28.0" lower="-6.28318530718" upper="6.28318530718" velocity="3.2"/>
    <dynamics damping="0.0" friction="0.0"/>
  </joint>
  <link name="wrist_1_link">
    <visual>
      <geometry>
        <mesh filename="ur5/visual/wrist1.dae"/>
      </geometry>
      <material name="LightGrey">
        <color rgba="0.7 0.7 0.7 1.0"/>
      </material>
    </visual>
    <collision>
      <geometry>
        <!-- <mesh filename="/home/quim/stg/quim-example-robot-data/example-robot-data/robots/ur_description/meshes/ur5/collision/wrist1.stl"/> -->
	<sphere  radius="0.06"/>
      </geometry>
    </collision>
    <inertial>
      <mass value="1.219"/>
      <origin rpy="0 0 0" xyz="0.0 0.0 0.0"/>
      <inertia ixx="0.111172755531" ixy="0.0" ixz="0.0" iyy="0.111172755531" iyz="0.0" izz="0.21942"/>
    </inertial>
  </link>
  <joint name="wrist_2_joint" type="revolute">
    <parent link="wrist_1_link"/>
    <child link="wrist_2_link"/>
    <origin rpy="0.0 0.0 0.0" xyz="0.0 0.093 0.0"/>
    <axis xyz="0 0 1"/>
    <limit effort="28.0" lower="-6.28318530718" upper="6.28318530718" velocity="3.2"/>
    <dynamics damping="0.0" friction="0.0"/>
  </joint>
  <link name="wrist_2_link">
    <visual>
      <geometry>
        <mesh filename="ur5/visual/wrist2.dae"/>
      </geometry>
      <material name="LightGrey">
        <color rgba="0.7 0.7 0.7 1.0"/>
      </material>
    </visual>
    <collision>
      <!-- <geometry> -->
      <!--   <mesh filename="/home/quim/stg/quim-example-robot-data/example-robot-data/robots/ur_description/meshes/ur5/collision/wrist2.stl"/> -->
      <!-- </geometry> -->
      <geometry>
	<sphere  radius="0.05"/>
      </geometry>
    </collision>
    <inertial>
      <mass value="1.219"/>
      <origin rpy="0 0 0" xyz="0.0 0.0 0.0"/>
      <inertia ixx="0.111172755531" ixy="0.0" ixz="0.0" iyy="0.111172755531" iyz="0.0" izz="0.21942"/>
    </inertial>
  </link>
  <joint name="wrist_3_joint" type="revolute">
    <parent link="wrist_2_link"/>
    <child link="wrist_3_link"/>
    <origin rpy="0.0 0.0 0.0" xyz="0.0 0.0 0.09465"/>
    <axis xyz="0 1 0"/>
    <limit effort="28.0" lower="-6.28318530718" upper="6.28318530718" velocity="3.2"/>
    <dynamics damping="0.0" friction="0.0"/>
  </joint>
  <link name="wrist_3_link">
    <visual>
      <geometry>
        <mesh filename="ur5/visual/wrist3.dae"/>
      </geometry>
      <material name="LightGrey">
        <color rgba="0.7 0.7 0.7 1.0"/>
      </material>
    </visual>
    <collision>
        <!-- <origin rpy="0.0 0.0 1.57079632679" xyz="0.0 0.0 0.0"/> -->
        <origin rpy="1.57079632679 0.0 0.0" xyz="0.0 0.0 0.0"/>
      <geometry>
        <!-- <mesh filename="/home/quim/stg/quim-example-robot-data/example-robot-data/robots/ur_description/meshes/ur5/collision/wrist3.stl"/> -->
	<cylinder  radius="0.04" length=".15"/>
      </geometry>
    </collision>
      <geometry>
	<sphere  radius="0.08"/>
      </geometry>
    <inertial>
      <mass value="0.1879"/>
      <origin rpy="0 0 0" xyz="0.0 0.0 0.0"/>
      <inertia ixx="0.0171364731454" ixy="0.0" ixz="0.0" iyy="0.0171364731454" iyz="0.0" izz="0.033822"/>
    </inertial>
  </link>
  <joint name="ee_fixed_joint" type="fixed">
    <parent link="wrist_3_link"/>
    <child link="ee_link"/>
    <origin rpy="0.0 0.0 1.57079632679" xyz="0.0 0.0823 0.0"/>
  </joint>
  <link name="ee_link">
    <inertial>
      <mass value="0"/>
      <origin rpy="0 0 0" xyz="0 0 0"/>
      <inertia ixx="0" ixy="0" ixz="0" iyy="0" iyz="0" izz="0"/>
    </inertial>
    <collision>
      <geometry>
	<sphere  radius="0.05"/>
      </geometry>
      <origin rpy="0 0 0" xyz="0.0 0 0"/>
    </collision>
  </link>
  <transmission name="shoulder_pan_trans">
    <type>transmission_interface/SimpleTransmission</type>
    <joint name="shoulder_pan_joint">
      <hardwareInterface>hardware_interface/PositionJointInterface</hardwareInterface>
    </joint>
    <actuator name="shoulder_pan_motor">
      <mechanicalReduction>1</mechanicalReduction>
    </actuator>
  </transmission>
  <transmission name="shoulder_lift_trans">
    <type>transmission_interface/SimpleTransmission</type>
    <joint name="shoulder_lift_joint">
      <hardwareInterface>hardware_interface/PositionJointInterface</hardwareInterface>
    </joint>
    <actuator name="shoulder_lift_motor">
      <mechanicalReduction>1</mechanicalReduction>
    </actuator>
  </transmission>
  <transmission name="elbow_trans">
    <type>transmission_interface/SimpleTransmission</type>
    <joint name="elbow_joint">
      <hardwareInterface>hardware_interface/PositionJointInterface</hardwareInterface>
    </joint>
    <actuator name="elbow_motor">
      <mechanicalReduction>1</mechanicalReduction>
    </actuator>
  </transmission>
  <transmission name="wrist_1_trans">
    <type>transmission_interface/SimpleTransmission</type>
    <joint name="wrist_1_joint">
      <hardwareInterface>hardware_interface/PositionJointInterface</hardwareInterface>
    </joint>
    <actuator name="wrist_1_motor">
      <mechanicalReduction>1</mechanicalReduction>
    </actuator>
  </transmission>
  <transmission name="wrist_2_trans">
    <type>transmission_interface/SimpleTransmission</type>
    <joint name="wrist_2_joint">
      <hardwareInterface>hardware_interface/PositionJointInterface</hardwareInterface>
    </joint>
    <actuator name="wrist_2_motor">
      <mechanicalReduction>1</mechanicalReduction>
    </actuator>
  </transmission>
  <transmission name="wrist_3_trans">
    <type>transmission_interface/SimpleTransmission</type>
    <joint name="wrist_3_joint">
      <hardwareInterface>hardware_interface/PositionJointInterface</hardwareInterface>
    </joint>
    <actuator name="wrist_3_motor">
      <mechanicalReduction>1</mechanicalReduction>
    </actuator>
  </transmission>
  <gazebo reference="shoulder_link">
    <selfCollide>true</selfCollide>
  </gazebo>
  <gazebo reference="upper_arm_link">
    <selfCollide>true</selfCollide>
  </gazebo>
  <gazebo reference="forearm_link">
    <selfCollide>true</selfCollide>
  </gazebo>
  <gazebo reference="wrist_1_link">
    <selfCollide>true</selfCollide>
  </gazebo>
  <gazebo reference="wrist_3_link">
    <selfCollide>true</selfCollide>
  </gazebo>
  <gazebo reference="wrist_2_link">
    <selfCollide>true</selfCollide>
  </gazebo>
  <gazebo reference="ee_link">
    <selfCollide>true</selfCollide>
  </gazebo>
  <!-- ROS base_link to UR 'Base' Coordinates transform -->
  <link name="base">
    <inertial>
      <mass value="0"/>
      <origin rpy="0 0 0" xyz="0 0 0"/>
      <inertia ixx="0" ixy="0" ixz="0" iyy="0" iyz="0" izz="0"/>
    </inertial>
  </link>
  <joint name="base_link-base_fixed_joint" type="fixed">
    <!-- NOTE: this rotation is only needed as long as base_link itself is
                 not corrected wrt the real robot (ie: rotated over 180
                 degrees)
      -->
    <origin rpy="0 0 -3.14159265359" xyz="0 0 0"/>
    <parent link="base_link"/>
    <child link="base"/>
  </joint>
  <!-- Frame coincident with all-zeros TCP on UR controller -->
  <link name="tool0">
    <inertial>
      <mass value="0"/>
      <origin rpy="0 0 0" xyz="0 0 0"/>
      <inertia ixx="0" ixy="0" ixz="0" iyy="0" iyz="0" izz="0"/>
    </inertial>
  </link>
  <joint name="wrist_3_link-tool0_fixed_joint" type="fixed">
    <origin rpy="-1.57079632679 0 0" xyz="0 0.0823 0"/>
    <parent link="wrist_3_link"/>
    <child link="tool0"/>
  </joint>
  <link name="world"/>
  <joint name="world_joint" type="fixed">
    <parent link="world"/>
    <child link="base_link"/>
    <origin rpy="0.0 0.0 0.0" xyz="0.0 0.0 0.0"/>
  </joint>


  <link name="box_1">
    <visual>
      <geometry>
	<box  size="0.05 0.55 0.55"/>
      </geometry>
      <material name="custom">
        <color rgba="0.8 0.7 0.7 0.55"/>
      </material>
    </visual>

    <collision>
      <geometry>
	<box  size="0.05 0.55 0.55"/>
      </geometry>
      <material name="custom">
        <color rgba="0.8 0.7 0.7 0.55"/>
      </material>
    </collision>



  </link>

  <link name="box_2">
    <visual>
      <geometry>
	<box  size="0.05 0.55 0.55"/>
      </geometry>
      <material name="custom">
        <color rgba="0.8 0.7 0.7 0.55"/>
      </material>
    </visual>

    <collision>
      <geometry>
	<box  size="0.05 0.55 0.55"/>
      </geometry>
      <material name="custom">
        <color rgba="0.8 0.7 0.7 0.55"/>
      </material>
    </collision>



  </link>

  <link name="box_3">
    <visual>
      <geometry>
	<box  size="0.05 0.55 0.55"/>
      </geometry>
      <material name="custom">
        <color rgba="0.8 0.7 0.7 0.55"/>
      </material>
    </visual>

    <collision>
      <geometry>
	<box  size="0.05 0.55 0.55"/>
      </geometry>
      <material name="custom">
        <color rgba="0.8 0.7 0.7 0.55"/>
      </material>
    </collision>


  </link>

  <link name="box_4">
    <visual>
      <geometry>
	<box  size="0.05 0.55 0.55"/>
      </geometry>
      <material name="custom">
        <color rgba="0.8 0.7 0.7 0.55"/>
      </material>
    </visual>


    <collision>
      <geometry>
	<box  size="0.05 0.55 0.55"/>
      </geometry>
      <material name="custom">
        <color rgba="0.8 0.7 0.7 0.55"/>
      </material>
    </collision>


  </link>

  <link name="base_box">
  </link>


  <joint name="base_box_j" type="fixed">
    <parent link="world"/>
    <child link="base_box"/>
    <origin rpy="0. 1.57 0." xyz="-.8 -0.1 0.45"/>
  </joint>



  <joint name="box_1j" type="fixed">
    <parent link="base_box"/>
    <child link="box_1"/>
    <origin rpy="0.0 0.0 0.0" xyz="-.3 0.0 .0"/>
  </joint>

  <joint name="box_2j" type="fixed">
    <parent link="base_box"/>
    <child link="box_2"/>
    <origin rpy="0.0 0.0 0.0" xyz=".3 0.0 .0"/>
  </joint>


  <joint name="box_3j" type="fixed">
    <parent link="base_box"/>
    <child link="box_3"/>
    <origin rpy="0.0 0.0 1.57" xyz="0.0 .3 .0"/>
  </joint>


  <joint name="box_4j" type="fixed">
    <parent link="base_box"/>
    <child link="box_4"/>
    <origin rpy="0.0 0.0 1.57" xyz="0.0 -.3 .0"/>
  </joint>



  <link name="table">
    <visual>
      <geometry>
	<box  size="1.5 1.5 .2"/>
      </geometry>
      <material name="custom">
        <color rgba="0.8 0.7 0.7 0.5"/>
      </material>
    </visual>


    <collision>
      <geometry>
	<box  size="1.5 1.5 .2"/>
      </geometry>
      <material name="custom">
        <color rgba="0.8 0.7 0.7 0.5"/>
      </material>
    </collision>


  </link>

  <joint name="table_j" type="fixed">
    <parent link="world"/>
    <child link="table"/>
    <origin rpy="0. 0 0." xyz="0 0 -0.1"/>
  </joint>




</robot>
